Workbook

Sheet ReadMe
A1: Interpreting the Russian Operations Against Europe Event Dataset
A2: 1 | B2: Event data collected on (attempted) sabotage, attacks & influence campaigns in the physical domain, or with a clear effect on a physical object / service / person.
A3: 2 | B3: As a result, cyber operations were largely left out of consideration, as hundreds if not thousands of incidents too many to tally in time available; only included when physical effect / consequence present (e.g., disruption of water works).
A4: 3 | B4: In many cases, attribution is difficult. We have erred on the side of caution, leaving out numerous incidents and suspicious accidents where suspicion of Russian involvement was too tenous (see Excluded).
A5: 4 | B5: We included cases when they a) were linked to Russia by the authorities / politicians, and / or b) appeared to fit in a pattern of similar attacks / events that had been 'officially' suspected of being linked to Russia, and / or c) where based on journalistic investigations that had uncovered hard evidence of a link to Russia (e.g., status reports to handlers, details of financial transactions, etc.)
A6: 5 | B6: The event data anly covers incidents initiated in the time period since the Russian invasion of Ukraine (February 2022).
A7: 6 | B7: The 'IncidentYear' field records the year when a particular operation was carried out, or an ongoing activity begun. It does not record the year of the publication in which the incident was reported.
A8: 7 | B8: Event data focuses solely on Europe, in particular European Union member states.
A9: 8 | B9: Only events ostensibly linked to the 2022 Russian invasion of Ukraine are recorded. This means that incidents such as the intimidation of Russian opposition members abroad, or espionage that cannot clearly be linked specifically to the invasion of Ukraine (e.g., espionage to prepare for sabotage against a country supporting Ukraine), are excluded.
A10: 9 | B10: Despite our best efforts and precautions, this event data should be treated as speculative, likely to be incomplete (underreporting the total number of incidents) and subject to change.
A11: 10 | B11: The primary purpose of this event data is to help inform the public debate on Russia's increasingly aggressive operations in Europe following its invasion of Ukraine by providing an overview of events & attacks related to the physical domain.
A13: Version: | B13: 46034
A14: Dataset repository | B14: https://doi.org/10.7910/DVN/TQ0FMQ
A15: Copyright: | B15: Dr. Bart Schuurman, Professor of Terrorism and Political Violence, Leiden University
A16: Contact: | B16: b.w.schuurman@fgga.leidenuniv.nl
A17: License: | B17: CC BY 4.0
A19: Acknowledgements: | B19: Maurits Huijbens, Dion Jordens, and Stijn Willem van 't Land assisted with data collection and validation. This project was supported by subsidy #3985535, awarded by the Dutch Minstry of Justice and Security in June 2022.
A20: Project website: | B20: https://bewakenenbeveiligen.universiteitleiden.nl/about
A22: Categories used
A23: Type of incident
A24: Sabotage | B24: Degrading or destroying infrastructure or facilities for political, economic or military advantage. Includes attempted and planned sabotage.
A25: Vandalism | B25: Deliberate destruction or damage to public or private property, here intended to serve political purposes such as sowing fear or chaos.
A26: Influence operation | B26: Campaigns or actions intended to influence the (political) views of European citizens or politicians, here with the aim of undermining support for Ukraine or destabilizing domestic / EU politics.
A27: Assassination | B27: Murder for political reasons. Includes plots and attempts.
A28: Disruptive immigration | B28: Deliberately creating large and/or enduring immigration / refugee flows towards EU member states' borders.
A29: Terrorism | B29: Deliberate use of deadly violence against civilian targets (e.g., transport aircraft) with the aim of influencing larger audiences beyond those targeted in furtherance of a political cause, e.g., to intimidate or inspire.
A30: Disruption | B30: (Attempted) disruption of (public) services, such as the operation of airports, without physical destruction of said services as would often be the case for sabotage.
A31: Arson | B31: (Attempted) desctruction of property through arson.
A32: Reconnaissance | B32: Gathering of information on critical infrastructure, potentially as preparation for sabotage.
A34: Apparent goal
A35: Dissuade defection | B35: Stop people from defecting from the Russian armed forces / state by demonstrating the potential costs (e.g., being killed) of doing so.
A36: Kill politician / head of state | B36: As described.
A37: Degrade military infrastructure | B37: Damaging or destroying military facilities / equipment.
A38: Disrupt (civil) aviation | B38: Interfering with the ability of (civil) aviation to operate safely, e.g. through GPS jamming or flying drones over airpots.
A39: Compromise public utilities | B39: Damaging or destroying public utilities such as water treatment plants, or engaging in preparations to do so.
A40: Degrade energy supply / commmunciations infrastructure | B40: Damageing or destroying the facilities or infrastructure involved in the provision of energy or enabling telecommunications, or engaging in preparations to do so (e.g., undersea cables).
A41: Compromise domestic / EU politics | B41: Attempts to influence politicians, political parties, or public opinion regarding politics such that pro-Russian voices become stronger, and / or support for Ukraine is undermined.
A42: Inflict economic damage | B42: Damaging or destroying buildings / facilities / infrastructure / services with the aim of causing economic damage.
A43: Disrupt (military) aid to Ukraine | B43: Physically degrading the ability of EU states to deliver aid to Ukraine (e.g., sabotating railroads) and / or underming public / political opinion such that aid for Ukraine is negatively affected.
A44: Disrupt daily life | B44: Attempts to influence EU citizen's daily life by damaging or destroying publc property / services, and / or spreading confusion / chaos among citizens with unexpected and stressful events such as vandalism, arson, intimidating displays.
...

Sheet EventData
A1: IncidentYear | B1: IncidentMonth | C1: IncidentDateRange | D1: IncidentDateStart | E1: IncidentDateEnd | F1: What | G1: Where | H1: EventCategory | I1: EventCategory2 | J1: ApparentGoal1 | K1: ApparentGoal2 | L1: TargetType | M1: TargetType2 | N1: DisposableAgentsInvolved | O1: For discussion | P1: Note
A2: 2022 | B2: January | C2: Yes | D2: 44562 | E2: 44926 | F2: Ongoing attempt to map offshore comms/energy infrastructure in North Sea / Baltic | G2: North Sea; Baltic Sea | H2: Reconnaissance | I2: Does not apply | J2: Preparation for potential sabotage | K2: Does not apply | L2: Energy / communications infrastructure | M2: Does not apply | O2: No | P2: Ongoing for years.
A3: 2022 | B3: March | C3: Yes | D3: 44621 | E3: 44803 | F3: Following Ru invasion, Marsalek-led Bulgarian spyring began a disinfo operation in Austria and Germany with stickers and graffiti. | G3: Austria; Germany | H3: Influence operation | I3: Does not apply | J3: Disrupt (military) aid to Ukraine | K3: Does not apply | L3: Public space: Shopping centre / Memorial / Landmark / Company / School | M3: Does not apply | N3: Yes | O3: No | P3: One of several operations conducted by the Bulgarian spy ring that was arrested in the UK in early 2023. Start and end-date not certain, but began shortly after invasion of Ukraine and seem to have ended by September, when new targets came into view.
A4: 2022 | B4: April | C4: No | D4: DNA | E4: DNA | F4: Spraypainting 'KILLNET HACKED YOU' on Cyber Defence Centre, Tallinn | G4: Estonia | H4: Vandalism | I4: Does not apply | J4: Disrupt daily life | K4: Does not apply | L4: Military / weapons production infrastructure | M4: Does not apply | O4: No
A5: 2022 | B5: April | C5: No | D5: DNA | E5: DNA | F5: Pro-Russian rallies / protest / vehicle parades in various European cities. Various experts suggest likely (partly) result of top-down pressure on Russian expats. | G5: Germany; Greece; Ireland; Cyprus | H5: Influence operation | I5: Does not apply | J5: Disrupt (military) aid to Ukraine | K5: Does not apply | L5: Public space: Shopping centre / Memorial / Landmark / Company / School | M5: Does not apply | N5: Unknown | O5: No
A6: 2022 | B6: May | C6: No | D6: DNA | E6: DNA | F6: Spionage of Lielvarde military airfield, near Rembate, Latvia | G6: Latvia | H6: Reconnaissance | I6: Does not apply | J6: Preparation for potential sabotage | K6: Does not apply | L6: Military / weapons production infrastructure | M6: Does not apply | O6: No
A7: 2022 | B7: May | C7: Yes | D7: 44682 | E7: 44926 | F7: Operation Doppelganger: Russian influence campaign that used faked websites (e.g., Der Spiegel, WaPo) to undermine Western support for Ukraine. Social Design Agency. Part of 'Comprehensive Counter Campaign' | G7: Germany; France; United Kingdom; Italy; United States; Ukraine; Latvia; Poland; The Netherlands | H7: Influence operation | I7: Does not apply | J7: Compromise domestic / EU politics | K7: Does not apply | L7: Internet / Social media / News | M7: Does not apply | O7: No | P7: See also: https://mpf.se/psychological-defence-agency/publications/archive/2025-05-15-beyond-operation-doppelganger-a-capability-assessment-of-the-social-design-agency
A8: 2022 | B8: June | C8: Yes | D8: 44713 | E8: 44926 | F8: Children of war campaign (Kinder des Krieges). Kremlin-backed and AFD supported campaign to sway public opinion against supporting Ukraine. | G8: Germany | H8: Influence operation | I8: Does not apply | J8: Disrupt (military) aid to Ukraine | K8: Does not apply | L8: Public space: Shopping centre / Memorial / Landmark / Company / School | M8: Does not apply | N8: No | O8: No
A9: 2022 | B9: July | C9: No | D9: DNA | E9: DNA | F9: Arms factory fire / explosion in Karnobat, Bulgaria 2022 | G9: Bulgaria | H9: Sabotage | I9: Does not apply | J9: Disrupt (military) aid to Ukraine | K9: Does not apply | L9: Military / weapons production infrastructure | M9: Does not apply | O9: No
A10: 2022 | B10: September | C10: Yes | D10: 44805 | E10: 44926 | F10: Building (far) left & (far) right-wing anti-war coaltion in Germany (Wagenknecht / AfD) | G10: Germany | H10: Influence operation | I10: Does not apply | J10: Disrupt (military) aid to Ukraine | K10: Compromise domestic / EU politics | L10: Politician(s) | M10: Does not apply | O10: No
A11: 2022 | B11: September | C11: Yes | D11: 44805 | E11: 44865 | F11: Russian nationals flying drones over Norwegian airports, energy infrastructure, photographing | G11: Norway | H11: Reconnaissance | I11: Disruption | J11: Preparation for potential sabotage | K11: Disrupt (civil) aviation | L11: Energy / communications infrastructure | M11: Civil aviation | O11: No
A12: 2022 | B12: October | C12: Yes | D12: 44835 | E12: 44926 | F12: Plot to use IMSI catchers to identify and locate Ukrainian soldiers training to operate Patriot missile batteries, to use as targeting information. Base being targeted was Patch Barracks near Stuttgart. Plot developed in UK. | G12: United Kingdom; Germany | H12: Reconnaissance | I12: Does not apply | J12: Preparation for potential sabotage | K12: Does not apply | L12: Military / weapons production infrastructure | M12: Does not apply | N12: Yes | O12: No | P12: Plot carried on until early 2023 but recorded in 2022 to avoid double-counting. One of several operations conducted by the Bulgarian spy ring that was arrested in the UK in early 2023.
A13: 2022 | B13: November | C13: Yes | D13: 44866 | E13: 44926 | F13: Six letter bombs sent to targets in Spain in Nov & Dec. Targeted Prime Minister, US & UKR embassies, defence ministry, arms manufacturer. Russian Imperial Movement suspected, acting on behalf of Ru intel | G13: Spain | H13: Terrorism | I13: Does not apply | J13: Disrupt (military) aid to Ukraine | K13: Does not apply | L13: Politician(s) / Official(s) | M13: Military / weapons production infrastructure | N13: No | O13: No | P13: Goal seems to be to signal intent / capability. But that could be argued for all of these operations. Going with undermining support for Ukraine as overarching motivation.
A14: 2022 | B14: December | C14: No | D14: DNA | E14: DNA | F14: Russian agents provocateur use two demonstrations in Paris to spread anti-Ukrainian propaganda. Presenting a protest about something else entirely as being against Western support for Ukraine. | G14: France | H14: Influence operation | I14: Does not apply | J14: Disrupt (military) aid to Ukraine | K14: Does not apply | L14: Public space: Shopping centre / Memorial / Landmark / Company / School | M14: Does not apply | N14: Unknown | O14: No | P14: Grouped these demonstrations by country / year. Not listing each demonstration individually.
A15: 2023 | B15: January | C15: Yes | D15: 44927 | E15: 45291 | F15: Building (far) left & (far) right-wing anti-war coaltion in Germany (Wagenknecht / AfD) | G15: Germany | H15: Influence operation | I15: Does not apply | J15: Disrupt (military) aid to Ukraine | K15: Compromise domestic / EU politics | L15: Politician(s) | M15: Does not apply | O15: No
A16: 2023 | B16: January | C16: Yes | D16: 44927 | E16: 45046 | F16: Russian agents provocateur use demonstrations across Europe to spread anti-Ukrainian propaganda. Presenting a protest about something else entirely as being against Western support for Ukraine. | G16: The Netherlands; Belgium; France; Spain | H16: Influence operation | I16: Does not apply | J16: Disrupt (military) aid to Ukraine | K16: Does not apply | L16: Public space: Shopping centre / Memorial / Landmark / Company / School | M16: Does not apply | N16: Unknown | O16: No
A17: 2023 | B17: January | C17: Yes | D17: 44927 | E17: 45291 | F17: Operation Doppelganger: Russian influence campaign that used faked websites (e.g., Der Spiegel, WaPo) to undermine Western support for Ukraine. Social Design Agency. Part of 'Comprehensive Counter Campaign' | G17: Germany; France; United Kingdom; Italy; United States; Ukraine; Latvia; Poland; The Netherlands | H17: Influence operation | I17: Does not apply | J17: Compromise domestic / EU politics | K17: Does not apply | L17: Internet / Social media / News | M17: Does not apply | O17: No | P17: See also: https://mpf.se/psychological-defence-agency/publications/archive/2025-05-15-beyond-operation-doppelganger-a-capability-assessment-of-the-social-design-agency
A18: 2023 | B18: January | C18: Yes | D18: 44927 | E18: 45291 | F18: Ongoing attempt to map offshore comms/energy infrastructure in North Sea / Baltic | G18: North Sea; Baltic Sea | H18: Reconnaissance | I18: Does not apply | J18: Preparation for potential sabotage | K18: Does not apply | L18: Energy / communications infrastructure | M18: Does not apply | O18: No | P18: Ongoing for years.
A19: 2023 | B19: January | C19: Yes | D19: 44927 | E19: 45291 | F19: Monthly 'Peace demonstations' on the Dam in Amsterdam. Monthly since approximately the Russian invasion of Ukraine in 2022. Organized by Dutch peace activists, but supported & financed by Russian organizations. | G19: The Netherlands | H19: Influence operation | I19: Does not apply | J19: Disrupt (military) aid to Ukraine | K19: Does not apply | L19: Public space: Shopping centre / Memorial / Landmark / Company / School | M19: Does not apply | N19: No | O19: No | P19: Appear to have begun in 2023 and to be ongoing in 2025. See: https://kyivindependent.com/who-is-behind-pro-russian-stop-zelensky-demonstrations-in-europe/
A20: 2023 | B20: January | C20: Yes | D20: 44927 | E20: 45291 | F20: Children of war campaign (Kinder des Krieges). Kremlin-backed and AFD supported campaign to sway public opinion against supporting Ukraine. | G20: Germany | H20: Influence operation | I20: Does not apply | J20: Disrupt (military) aid to Ukraine | K20: Does not apply | L20: Public space: Shopping centre / Memorial / Landmark / Company / School | M20: Does not apply | N20: No | O20: No
A21: 2023 | B21: January | C21: No | D21: DNA | E21: DNA | F21: Explosives cache found near NATO pipeline in Germany | G21: Germany | H21: Sabotage (preparation) | I21: Does not apply | J21: Degrade military infrastructure | K21: Does not apply | L21: Military / weapons production infrastructure | M21: Does not apply | O21: No | P21: May 2024 reporting cites security sources saying the cache was likely prepared 12 to 18 months ago. Taking average of 15 months as starting point, i.e. January 2023.
A22: 2023 | B22: January | C22: Yes | D22: 44927 | E22: 45016 | F22: Attempt to sabotage arms deliveries to Ukraine in Poland, plant cameras, recruit Ukrainian refugees | G22: Poland | H22: Sabotage (preparation) | I22: Does not apply | J22: Disrupt (military) aid to Ukraine | K22: Does not apply | L22: Transport infrastructure | M22: Does not apply | O22: No | P22: See this source for timing the start of this operation to at least January 2023: https://www.pap.pl/aktualnosci/ekspert-ludzie-czasem-nawet-nie-wiedza-ze-dzialaja-na-zlecenie-rosjan
A23: 2023 | B23: March | C23: No | D23: DNA | E23: DNA | F23: Arms factory fire / explosion in Karnobat, Bulgaria 2023 | G23: Bulgaria | H23: Sabotage | I23: Does not apply | J23: Disrupt (military) aid to Ukraine | K23: Does not apply | L23: Military / weapons production infrastructure | M23: Does not apply | O23: No
A24: 2023 | B24: March | C24: Yes | D24: 44986 | E24: 45291 | F24: Voice of Europe, cash payments to anti-establishment politicians, Russian attempt to influence EU Parliament elections | G24: Germany;Belgium;France;Czechia;Netherlands; | H24: Influence operation | I24: Does not apply | J24: Compromise domestic / EU politics | K24: Disrupt (military) aid to Ukraine | L24: Politician(s) | M24: Does not apply | O24: No | P24: See Wiki for details on period of operation: https://en.wikipedia.org/wiki/Voice_of_Europe#:~:text=The%20organization%20allegedly%20funneled%20up,candidates%20in%20European%20Parliament%20elections.
A25: 2023 | B25: May | C25: No | D25: DNA | E25: DNA | F25: Descecration of Sinimäed and Narva-Jõesuu memorial sites Estonia | G25: Estonia | H25: Vandalism | I25: Does not apply | J25: Disrupt daily life | K25: Does not apply | L25: Memorial sites / Landmarks | M25: Does not apply | N25: Yes
A26: 2023 | B26: June | C26: Yes | D26: 45078 | E26: 45291 | F26: Portal Kombat / Pravda network: websites disseminating pro-Russian content on war in Ukraine to Western audiences (ongoing) | G26: France; Germany; Austria; Switzerland; Poland; Spain; United Kingdom; United States | H26: Influence operation | I26: Does not apply | J26: Compromise domestic / EU politics | K26: Does not apply | L26: Internet / Social media / News | M26: Does not apply | O26: No
A27: 2023 | B27: July | C27: No | D27: DNA | E27: DNA | F27: Sweden targeted by Russia-backed disinformation campaign to undermine its NATO membership, claims that Sweden supports burning Quran | G27: Sweden | H27: Influence operation | I27: Does not apply | J27: Compromise domestic / EU politics | K27: Does not apply | L27: Internet / Social media / News | M27: Does not apply | O27: No
A28: 2023 | B28: August | C28: Yes | D28: 45139 | E28: 45291 | F28: GPS jamming & spoofing over Baltic Sea. As well as near Black Sea | G28: Baltic Sea; Finland; Latvia; Lithuania; Poland; Romania; Bulgaria | H28: Disruption | I28: Does not apply | J28: Disrupt (civil) aviation | K28: Does not apply | L28: Civil aviation | M28: Does not apply | O28: No
A29: 2023 | B29: August | C29: Yes | D29: 45139 | E29: 45199 | F29: Sending illegal immigrants towards Latvia: through Belarus. Appears to have been a peak in these months that was likely orchestrated. | G29: Latvia | H29: Disruptive immigration | I29: Does not apply | J29: Disrupt daily life | K29: Does not apply | L29: Border | M29: Does not apply | O29: No
A30: 2023 | B30: September | C30: Yes | D30: 45170 | E30: 45291 | F30: Pro-Russian campaign to influence 2024 EU parliamentary elections by Jean-Luc Schaffhauser | G30: France | H30: Influence operation | I30: Does not apply | J30: Compromise domestic / EU politics | K30: Disrupt (military) aid to Ukraine | L30: Politician(s) | M30: Does not apply | O30: No
A31: 2023 | B31: October | C31: No | D31: DNA | E31: DNA | F31: Gas & telecom cables Finland - Estonia damaged / NewNew Polar Bear incident | G31: Baltic Sea | H31: Sabotage | I31: Does not apply | J31: Degrade energy supply / communications infrastructure | K31: Does not apply | L31: Energy / communications infrastructure | M31: Does not apply | O31: No
A32: 2023 | B32: October | C32: Yes | D32: 45200 | E32: 45291 | F32: Russians amplify 'bed bug' panic on social media, Paris, France, fall 2023 | G32: France | H32: Influence operation | I32: Does not apply | J32: Disrupt daily life | K32: Does not apply | L32: Internet / Social media / News | M32: Does not apply | O32: No
A33: 2023 | B33: October | C33: No | D33: DNA | E33: DNA | F33: Hundreds of bomb threats emailed to schools in the Latvia, Estonia, Lithuania. Messages in Russian. Lithuanian security service sees 'hostile states' behind it. | G33: Estonia; Latvia; Lithuania | H33: Terrorism | I33: Does not apply | J33: Disrupt daily life | K33: Does not apply | L33: Public space: Shopping centre / Memorial / Landmark / Company / School | M33: Does not apply | O33: Yes | P33: Although Russia not directly named, link to hostile state made in public and fits pattern. Bomb threats seen as threat of violence against civilians, hence treated as terrorism.
A34: 2023 | B34: November | C34: No | D34: DNA | E34: DNA | F34: Stars of David graffiti in Paris, suspected Russian influence op | G34: France | H34: Vandalism | I34: Does not apply | J34: Disrupt daily life | K34: Does not apply | L34: Public space: Shopping centre / Memorial / Landmark / Company / School | M34: Does not apply | O34: No
A35: 2023 | B35: November | C35: Yes | D35: 45139 | E35: 45291 | F35: Russia sends large number immigrants towards Finish border | G35: Finland | H35: Disruptive immigration | I35: Does not apply | J35: Disrupt daily life | K35: Does not apply | L35: Border | M35: Does not apply | O35: No | P35: Apparently the flow of migrants stopped after Finland closed its border with Russia at the end of 2023: https://www.reuters.com/world/europe/finnish-government-seeks-extend-ban-migrants-seeking-asylum-russia-border-2025-03-27/
A36: 2023 | B36: November | C36: No | D36: DNA | E36: DNA | F36: Sending illegal immigrants towards Estonia. No reporting to suggest this particular spike persisted for very long. | G36: Estonia | H36: Disruptive immigration | I36: Does not apply | J36: Disrupt daily life | K36: Does not apply | L36: Border | M36: Does not apply | O36: No
A37: 2023 | B37: December | C37: No | D37: DNA | E37: DNA | F37: Vandalizing car of Estonian interior minister | G37: Estonia | H37: Vandalism | I37: Does not apply | J37: Intimidate politician / journalist | K37: Does not apply | L37: Politician(s) | M37: Does not apply | O37: No
A38: 2023 | B38: December | C38: No | D38: DNA | E38: DNA | F38: Vandalizing car of Estonian journalist | G38: Estonia | H38: Vandalism | I38: Does not apply | J38: Intimidate politician / journalist | K38: Does not apply | L38: Journalist(s) | M38: Does not apply | O38: No
A39: 2024 | B39: January | C39: No | D39: DNA | E39: DNA | F39: Sending illegal immigrants towards Finland. Coded as 1 month incident as unclear whether this persisted, see also link at end of entry. | G39: Finland | H39: Disruptive immigration | I39: Does not apply | J39: Disrupt daily life | K39: Does not apply | L39: Border | M39: Does not apply | O39: No | P39: https://www.reuters.com/world/europe/finnish-government-seeks-extend-ban-migrants-seeking-asylum-russia-border-2025-03-27/
A40: 2024 | B40: January | C40: No | D40: DNA | E40: DNA | F40: Arson attempt on paint factory / fuel depot Wroclaw, Poland | G40: Poland | H40: Arson | I40: Does not apply | J40: Inflict economic damage | K40: Does not apply | L40: Energy / communications infrastructure | M40: Does not apply | O40: No | P40: Further details: https://notesfrompoland.com/2025/02/21/poland-jails-ukrainian-for-eight-years-for-preparing-sabotage-on-behalf-of-russia/
...

Sheet Visualization
A1: Year | B1: No. Of incidents | C1: Excluded incidents | D1: Excluded Ratio | F1: MonthStart | G1: Multi-month operations | H1: Single-month operations | I1: TotalOpsPerMonth | K1: Type of incident | L1: 2022 | M1: 2023 | N1: 2024 | O1: 2025 | P1: Totals | R1: Apparent Goal | S1: 2022 | T1: 2023 | U1: 2024 | V1: 2025 | W1: Totals | Y1: Type of target | Z1: 2022 | AA1: 2023 | AB1: 2024 | AC1: 2025 | AD1: Totals | AF1: Locations targeted | AG1: 2022 | AH1: 2023 | AI1: 2024 | AJ1: 2025 | AK1: Totals
A2: 2022 | B2: =COUNTIF(EventData!A:A, "2022") -> 13 | C2: =COUNTIF(Excluded!A:A,"2022") -> 11 | D2: =C2/(SUM(B2:C2)) -> 0.45833333 | F2: 44562 | G2: =COUNTIFS(EventData!D:D,"<=" & EOMONTH(F2,0),EventData!E:E,">=" & F2) -> 1 | H2: =COUNTIFS(EventData!A:A,YEAR(F2),EventData!B:B,TEXT(F2,"mmmm"),EventData!C:C,"NO") -> 0 | I2: =SUM(G2:H2) -> 1 | K2: Assassination** | L2: =COUNTIFS(EventData!A:A,"2022",EventData!H:H,"*assassination*")+COUNTIFS(EventData!A:A,"2022",EventData!I:I,"*assassination*") -> 0 | M2: =COUNTIFS(EventData!A:A,"2023",EventData!H:H,"*assassination*")+COUNTIFS(EventData!A:A,"2023",EventData!I:I,"*assassination*") -> 0 | N2: =COUNTIFS(EventData!A:A,"2024",EventData!H:H,"*assassination*")+COUNTIFS(EventData!A:A,"2024",EventData!I:I,"*assassination*") -> 3 | O2: =COUNTIFS(EventData!A:A,"2025",EventData!H:H,"*assassination*")+COUNTIFS(EventData!A:A,"2025",EventData!I:I,"*assassination*") -> 0 | P2: =SUM(L2:O2) -> 3 | R2: Dissuade defection | S2: =COUNTIFS(EventData!A:A,"2022",EventData!J:J,"Dissuade defection")+COUNTIFS(EventData!A:A,"2022",EventData!K:K,"Dissuade defection") -> 0 | T2: =COUNTIFS(EventData!A:A,"2023",EventData!J:J,"Dissuade defection")+COUNTIFS(EventData!A:A,"2023",EventData!K:K,"Dissuade defection") -> 0 | U2: =COUNTIFS(EventData!A:A,"2024",EventData!J:J,"Dissuade defection")+COUNTIFS(EventData!A:A,"2024",EventData!K:K,"Dissuade defection") -> 1 | V2: =COUNTIFS(EventData!A:A,"2025",EventData!J:J,"Dissuade defection")+COUNTIFS(EventData!A:A,"2025",EventData!K:K,"Dissuade defection") -> 0 | W2: =SUM(S2:V2) -> 1 | Y2: Industrialist(s) | Z2: =COUNTIFS(EventData!A:A,"2022",EventData!L:L,"industrialist(s)")+COUNTIFS(EventData!A:A,"2022",EventData!M:M,"industrialist(s)") -> 0 | AA2: =COUNTIFS(EventData!A:A,"2023",EventData!L:L,"industrialist(s)")+COUNTIFS(EventData!A:A,"2023",EventData!M:M,"industrialist(s)") -> 0 | AB2: =COUNTIFS(EventData!A:A,"2024",EventData!L:L,"industrialist(s)")+COUNTIFS(EventData!A:A,"2024",EventData!M:M,"industrialist(s)") -> 1 | AC2: =COUNTIFS(EventData!A:A,"2025",EventData!L:L,"industrialist(s)")+COUNTIFS(EventData!A:A,"2025",EventData!M:M,"industrialist(s)") -> 0 | AD2: =SUM(Z2:AC2) -> 1 | AF2: Germany | AG2: =COUNTIFS(EventData!A:A,"2022",EventData!G:G,"*germany*") -> 6 | AH2: =COUNTIFS(EventData!A:A,"2023",EventData!G:G,"*germany*") -> 6 | AI2: =COUNTIFS(EventData!A:A,"2024",EventData!G:G,"*germany*") -> 14 | AJ2: =COUNTIFS(EventData!A:A,"2025",EventData!G:G,"*germany*") -> 10 | AK2: =SUM(AG2:AJ2) -> 36
A3: 2023 | B3: =COUNTIF(EventData!A:A, "2023") -> 24 | C3: =COUNTIF(Excluded!A:A,"2023") -> 3 | D3: =C3/(SUM(B3:C3)) -> 0.11111111 | F3: 44593 | G3: =COUNTIFS(EventData!D:D,"<=" & EOMONTH(F3,0),EventData!E:E,">=" & F3) -> 1 | H3: =COUNTIFS(EventData!A:A,YEAR(F3),EventData!B:B,TEXT(F3,"mmmm"),EventData!C:C,"NO") -> 0 | I3: =SUM(G3:H3) -> 1 | K3: Unknown | L3: =COUNTIFS(EventData!A:A,"2022",EventData!H:H,"*unknown*")+COUNTIFS(EventData!A:A,"2022",EventData!I:I,"*unknown*") -> 0 | M3: =COUNTIFS(EventData!A:A,"2023",EventData!H:H,"*unknown*")+COUNTIFS(EventData!A:A,"2023",EventData!I:I,"*unknown*") -> 0 | N3: =COUNTIFS(EventData!A:A,"2024",EventData!H:H,"*unknown*")+COUNTIFS(EventData!A:A,"2024",EventData!I:I,"*unknown*") -> 2 | O3: =COUNTIFS(EventData!A:A,"2025",EventData!H:H,"*unknown*")+COUNTIFS(EventData!A:A,"2025",EventData!I:I,"*unknown*") -> 2 | P3: =SUM(L3:O3) -> 4 | R3: Kill politician / head of state | S3: =COUNTIFS(EventData!A:A,"2022",EventData!J:J,"Kill politician*")+COUNTIFS(EventData!A:A,"2022",EventData!K:K,"Kill politician*") -> 0 | T3: =COUNTIFS(EventData!A:A,"2023",EventData!J:J,"Kill politician*")+COUNTIFS(EventData!A:A,"2023",EventData!K:K,"Kill politician*") -> 0 | U3: =COUNTIFS(EventData!A:A,"2024",EventData!J:J,"Kill politician*")+COUNTIFS(EventData!A:A,"2024",EventData!K:K,"Kill politician*") -> 1 | V3: =COUNTIFS(EventData!A:A,"2025",EventData!J:J,"Kill politician*")+COUNTIFS(EventData!A:A,"2025",EventData!K:K,"Kill politician*") -> 0 | W3: =SUM(S3:V3) -> 1 | Y3: Defector(s) | Z3: =COUNTIFS(EventData!A:A,"2022",EventData!L:L,"defector(s)")+COUNTIFS(EventData!A:A,"2022",EventData!M:M,"defector(s)") -> 0 | AA3: =COUNTIFS(EventData!A:A,"2023",EventData!L:L,"defector(s)")+COUNTIFS(EventData!A:A,"2023",EventData!M:M,"defector(s)") -> 0 | AB3: =COUNTIFS(EventData!A:A,"2024",EventData!L:L,"defector(s)")+COUNTIFS(EventData!A:A,"2024",EventData!M:M,"defector(s)") -> 1 | AC3: =COUNTIFS(EventData!A:A,"2025",EventData!L:L,"defector(s)")+COUNTIFS(EventData!A:A,"2025",EventData!M:M,"defector(s)") -> 0 | AD3: =SUM(Z3:AC3) -> 1 | AF3: Poland | AG3: =COUNTIFS(EventData!A:A,"2022",EventData!G:G,"*poland*") -> 1 | AH3: =COUNTIFS(EventData!A:A,"2023",EventData!G:G,"*poland*") -> 4 | AI3: =COUNTIFS(EventData!A:A,"2024",EventData!G:G,"*poland*") -> 17 | AJ3: =COUNTIFS(EventData!A:A,"2025",EventData!G:G,"*poland*") -> 8 | AK3: =SUM(AG3:AJ3) -> 30
A4: 2024 | B4: =COUNTIF(EventData!A:A, "2024") -> 69 | C4: =COUNTIF(Excluded!A:A,"2024") -> 25 | D4: =C4/(SUM(B4:C4)) -> 0.26595745 | F4: 44621 | G4: =COUNTIFS(EventData!D:D,"<=" & EOMONTH(F4,0),EventData!E:E,">=" & F4) -> 2 | H4: =COUNTIFS(EventData!A:A,YEAR(F4),EventData!B:B,TEXT(F4,"mmmm"),EventData!C:C,"NO") -> 0 | I4: =SUM(G4:H4) -> 2 | K4: Disruptive immigration | L4: =COUNTIFS(EventData!A:A,"2022",EventData!H:H,"*immigration*")+COUNTIFS(EventData!A:A,"2022",EventData!I:I,"*immigration*") -> 0 | M4: =COUNTIFS(EventData!A:A,"2023",EventData!H:H,"*immigration*")+COUNTIFS(EventData!A:A,"2023",EventData!I:I,"*immigration*") -> 3 | N4: =COUNTIFS(EventData!A:A,"2024",EventData!H:H,"*immigration*")+COUNTIFS(EventData!A:A,"2024",EventData!I:I,"*immigration*") -> 1 | O4: =COUNTIFS(EventData!A:A,"2025",EventData!H:H,"*immigration*")+COUNTIFS(EventData!A:A,"2025",EventData!I:I,"*immigration*") -> 1 | P4: =SUM(L4:O4) -> 5 | R4: Degrade military infrastructure | S4: =COUNTIFS(EventData!A:A,"2022",EventData!J:J,"Degrade military infrastructure")+COUNTIFS(EventData!A:A,"2022",EventData!K:K,"Degrade military infrastructure") -> 0 | T4: =COUNTIFS(EventData!A:A,"2023",EventData!J:J,"Degrade military infrastructure")+COUNTIFS(EventData!A:A,"2023",EventData!K:K,"Degrade military infrastructure") -> 1 | U4: =COUNTIFS(EventData!A:A,"2024",EventData!J:J,"Degrade military infrastructure")+COUNTIFS(EventData!A:A,"2024",EventData!K:K,"Degrade military infrastructure") -> 0 | V4: =COUNTIFS(EventData!A:A,"2025",EventData!J:J,"Degrade military infrastructure")+COUNTIFS(EventData!A:A,"2025",EventData!K:K,"Degrade military infrastructure") -> 1 | W4: =SUM(S4:V4) -> 2 | Y4: Journalist(s) | Z4: =COUNTIFS(EventData!A:A,"2022",EventData!L:L,"journalist(s)")+COUNTIFS(EventData!A:A,"2022",EventData!M:M,"journalist(s)") -> 0 | AA4: =COUNTIFS(EventData!A:A,"2023",EventData!L:L,"journalist(s)")+COUNTIFS(EventData!A:A,"2023",EventData!M:M,"journalist(s)") -> 1 | AB4: =COUNTIFS(EventData!A:A,"2024",EventData!L:L,"journalist(s)")+COUNTIFS(EventData!A:A,"2024",EventData!M:M,"journalist(s)") -> 0 | AC4: =COUNTIFS(EventData!A:A,"2025",EventData!L:L,"journalist(s)")+COUNTIFS(EventData!A:A,"2025",EventData!M:M,"journalist(s)") -> 0 | AD4: =SUM(Z4:AC4) -> 1 | AF4: France | AG4: =COUNTIFS(EventData!A:A,"2022",EventData!G:G,"*france*") -> 2 | AH4: =COUNTIFS(EventData!A:A,"2023",EventData!G:G,"*france*") -> 7 | AI4: =COUNTIFS(EventData!A:A,"2024",EventData!G:G,"*france*") -> 14 | AJ4: =COUNTIFS(EventData!A:A,"2025",EventData!G:G,"*france*") -> 6 | AK4: =SUM(AG4:AJ4) -> 29
A5: 2025 | B5: =COUNTIF(EventData!A:A, "2025") -> 40 | C5: =COUNTIF(Excluded!A:A,"2025") -> 39 | D5: =C5/(SUM(B5:C5)) -> 0.49367089 | F5: 44652 | G5: =COUNTIFS(EventData!D:D,"<=" & EOMONTH(F5,0),EventData!E:E,">=" & F5) -> 2 | H5: =COUNTIFS(EventData!A:A,YEAR(F5),EventData!B:B,TEXT(F5,"mmmm"),EventData!C:C,"NO") -> 2 | I5: =SUM(G5:H5) -> 4 | K5: Terrorism* | L5: =COUNTIFS(EventData!A:A,"2022",EventData!H:H,"*terrorism*")+COUNTIFS(EventData!A:A,"2022",EventData!I:I,"*terrorism*") -> 1 | M5: =COUNTIFS(EventData!A:A,"2023",EventData!H:H,"*terrorism*")+COUNTIFS(EventData!A:A,"2023",EventData!I:I,"*terrorism*") -> 1 | N5: =COUNTIFS(EventData!A:A,"2024",EventData!H:H,"*terrorism*")+COUNTIFS(EventData!A:A,"2024",EventData!I:I,"*terrorism*") -> 5 | O5: =COUNTIFS(EventData!A:A,"2025",EventData!H:H,"*terrorism*")+COUNTIFS(EventData!A:A,"2025",EventData!I:I,"*terrorism*") -> 2 | P5: =SUM(L5:O5) -> 9 | R5: Intimidate politician / journalist | S5: =COUNTIFS(EventData!A:A,"2022",EventData!J:J,"*intimidate*")+COUNTIFS(EventData!A:A,"2022",EventData!K:K,"*intimidate*") -> 0 | T5: =COUNTIFS(EventData!A:A,"2023",EventData!J:J,"*intimidate*")+COUNTIFS(EventData!A:A,"2023",EventData!K:K,"*intimidate*") -> 2 | U5: =COUNTIFS(EventData!A:A,"2024",EventData!J:J,"*intimidate*")+COUNTIFS(EventData!A:A,"2024",EventData!K:K,"*intimidate*") -> 0 | V5: =COUNTIFS(EventData!A:A,"2025",EventData!J:J,"*intimidate*")+COUNTIFS(EventData!A:A,"2025",EventData!K:K,"*intimidate*") -> 1 | W5: =SUM(S5:V5) -> 3 | Y5: Economic infrastructure | Z5: =COUNTIFS(EventData!A:A,"2022",EventData!L:L,"*economic infra*")+COUNTIFS(EventData!A:A,"2022",EventData!M:M,"*economic infra*") -> 0 | AA5: =COUNTIFS(EventData!A:A,"2023",EventData!L:L,"*economic infra*")+COUNTIFS(EventData!A:A,"2023",EventData!M:M,"*economic infra*") -> 0 | AB5: =COUNTIFS(EventData!A:A,"2024",EventData!L:L,"*economic infra*")+COUNTIFS(EventData!A:A,"2024",EventData!M:M,"*economic infra*") -> 0 | AC5: =COUNTIFS(EventData!A:A,"2025",EventData!L:L,"*economic infra*")+COUNTIFS(EventData!A:A,"2025",EventData!M:M,"*economic infra*") -> 1 | AD5: =SUM(Z5:AC5) -> 1 | AF5: The Netherlands | AG5: =COUNTIFS(EventData!A:A,"2022",EventData!G:G,"*netherlands*") -> 1 | AH5: =COUNTIFS(EventData!A:A,"2023",EventData!G:G,"*netherlands*") -> 4 | AI5: =COUNTIFS(EventData!A:A,"2024",EventData!G:G,"*netherlands*") -> 7 | AJ5: =COUNTIFS(EventData!A:A,"2025",EventData!G:G,"*netherlands*") -> 3 | AK5: =SUM(AG5:AJ5) -> 15
A6: Totals | B6: =SUM(B2:B5) -> 146 | C6: =SUM(C2:C5) -> 78 | D6: =C6/(SUM(B6:C6)) -> 0.34821429 | F6: 44682 | G6: =COUNTIFS(EventData!D:D,"<=" & EOMONTH(F6,0),EventData!E:E,">=" & F6) -> 3 | H6: =COUNTIFS(EventData!A:A,YEAR(F6),EventData!B:B,TEXT(F6,"mmmm"),EventData!C:C,"NO") -> 1 | I6: =SUM(G6:H6) -> 4 | K6: Vandalism | L6: =COUNTIFS(EventData!A:A,"2022",EventData!H:H,"*vandalism*")+COUNTIFS(EventData!A:A,"2022",EventData!I:I,"*vandalism*") -> 1 | M6: =COUNTIFS(EventData!A:A,"2023",EventData!H:H,"*vandalism*")+COUNTIFS(EventData!A:A,"2023",EventData!I:I,"*vandalism*") -> 4 | N6: =COUNTIFS(EventData!A:A,"2024",EventData!H:H,"*vandalism*")+COUNTIFS(EventData!A:A,"2024",EventData!I:I,"*vandalism*") -> 6 | O6: =COUNTIFS(EventData!A:A,"2025",EventData!H:H,"*vandalism*")+COUNTIFS(EventData!A:A,"2025",EventData!I:I,"*vandalism*") -> 1 | P6: =SUM(L6:O6) -> 12 | R6: Compromise public utilities | S6: =COUNTIFS(EventData!A:A,"2022",EventData!J:J,"Compromise public utilities")+COUNTIFS(EventData!A:A,"2022",EventData!K:K,"Compromise public utilities") -> 0 | T6: =COUNTIFS(EventData!A:A,"2023",EventData!J:J,"Compromise public utilities")+COUNTIFS(EventData!A:A,"2023",EventData!K:K,"Compromise public utilities") -> 0 | U6: =COUNTIFS(EventData!A:A,"2024",EventData!J:J,"Compromise public utilities")+COUNTIFS(EventData!A:A,"2024",EventData!K:K,"Compromise public utilities") -> 3 | V6: =COUNTIFS(EventData!A:A,"2025",EventData!J:J,"Compromise public utilities")+COUNTIFS(EventData!A:A,"2025",EventData!K:K,"Compromise public utilities") -> 1 | W6: =SUM(S6:V6) -> 4 | Y6: Arms deliveries to Ukraine | Z6: =COUNTIFS(EventData!A:A,"2022",EventData!L:L,"Arms deliveries to Ukraine")+COUNTIFS(EventData!A:A,"2022",EventData!M:M,"Arms deliveries to Ukraine") -> 0 | AA6: =COUNTIFS(EventData!A:A,"2023",EventData!L:L,"Arms deliveries to Ukraine")+COUNTIFS(EventData!A:A,"2023",EventData!M:M,"Arms deliveries to Ukraine") -> 0 | AB6: =COUNTIFS(EventData!A:A,"2024",EventData!L:L,"Arms deliveries to Ukraine")+COUNTIFS(EventData!A:A,"2024",EventData!M:M,"Arms deliveries to Ukraine") -> 1 | AC6: =COUNTIFS(EventData!A:A,"2025",EventData!L:L,"Arms deliveries to Ukraine")+COUNTIFS(EventData!A:A,"2025",EventData!M:M,"Arms deliveries to Ukraine") -> 1 | AD6: =SUM(Z6:AC6) -> 2 | AF6: United Kingdom | AG6: =COUNTIFS(EventData!A:A,"2022",EventData!G:G,"*united kingdom*") -> 2 | AH6: =COUNTIFS(EventData!A:A,"2023",EventData!G:G,"*united kingdom*") -> 2 | AI6: =COUNTIFS(EventData!A:A,"2024",EventData!G:G,"*united kingdom*") -> 4 | AJ6: =COUNTIFS(EventData!A:A,"2025",EventData!G:G,"*united kingdom*") -> 3 | AK6: =SUM(AG6:AJ6) -> 11
F7: 44713 | G7: =COUNTIFS(EventData!D:D,"<=" & EOMONTH(F7,0),EventData!E:E,">=" & F7) -> 4 | H7: =COUNTIFS(EventData!A:A,YEAR(F7),EventData!B:B,TEXT(F7,"mmmm"),EventData!C:C,"NO") -> 0 | I7: =SUM(G7:H7) -> 4 | K7: Disruption | L7: =COUNTIFS(EventData!A:A,"2022",EventData!H:H,"disruption")+COUNTIFS(EventData!A:A,"2022",EventData!I:I,"disruption") -> 1 | M7: =COUNTIFS(EventData!A:A,"2023",EventData!H:H,"disruption")+COUNTIFS(EventData!A:A,"2023",EventData!I:I,"disruption") -> 1 | N7: =COUNTIFS(EventData!A:A,"2024",EventData!H:H,"disruption")+COUNTIFS(EventData!A:A,"2024",EventData!I:I,"disruption") -> 2 | O7: =COUNTIFS(EventData!A:A,"2025",EventData!H:H,"disruption")+COUNTIFS(EventData!A:A,"2025",EventData!I:I,"disruption") -> 9 | P7: =SUM(L7:O7) -> 13 | R7: Degrade energy supply / communications infrastructure | S7: =COUNTIFS(EventData!A:A,"2022",EventData!J:J,"Degrade energy supply / communications infrastructure")+COUNTIFS(EventData!A:A,"2022",EventData!K:K,"Degrade energy supply / communications infrastructure") -> 0 | T7: =COUNTIFS(EventData!A:A,"2023",EventData!J:J,"Degrade energy supply / communications infrastructure")+COUNTIFS(EventData!A:A,"2023",EventData!K:K,"Degrade energy supply / communications infrastructure") -> 1 | U7: =COUNTIFS(EventData!A:A,"2024",EventData!J:J,"Degrade energy supply / communications infrastructure")+COUNTIFS(EventData!A:A,"2024",EventData!K:K,"Degrade energy supply / communications infrastructure") -> 3 | V7: =COUNTIFS(EventData!A:A,"2025",EventData!J:J,"Degrade energy supply / communications infrastructure")+COUNTIFS(EventData!A:A,"2025",EventData!K:K,"Degrade energy supply / communications infrastructure") -> 2 | W7: =SUM(S7:V7) -> 6 | Y7: Border | Z7: =COUNTIFS(EventData!A:A,"2022",EventData!L:L,"Border")+COUNTIFS(EventData!A:A,"2022",EventData!M:M,"Border") -> 0 | AA7: =COUNTIFS(EventData!A:A,"2023",EventData!L:L,"Border")+COUNTIFS(EventData!A:A,"2023",EventData!M:M,"Border") -> 3 | AB7: =COUNTIFS(EventData!A:A,"2024",EventData!L:L,"Border")+COUNTIFS(EventData!A:A,"2024",EventData!M:M,"Border") -> 2 | AC7: =COUNTIFS(EventData!A:A,"2025",EventData!L:L,"Border")+COUNTIFS(EventData!A:A,"2025",EventData!M:M,"Border") -> 1 | AD7: =SUM(Z7:AC7) -> 6 | AF7: Latvia | AG7: =COUNTIFS(EventData!A:A,"2022",EventData!G:G,"*latvia*") -> 2 | AH7: =COUNTIFS(EventData!A:A,"2023",EventData!G:G,"*latvia*") -> 4 | AI7: =COUNTIFS(EventData!A:A,"2024",EventData!G:G,"*latvia*") -> 3 | AJ7: =COUNTIFS(EventData!A:A,"2025",EventData!G:G,"*latvia*") -> 2 | AK7: =SUM(AG7:AJ7) -> 11
F8: 44743 | G8: =COUNTIFS(EventData!D:D,"<=" & EOMONTH(F8,0),EventData!E:E,">=" & F8) -> 4 | H8: =COUNTIFS(EventData!A:A,YEAR(F8),EventData!B:B,TEXT(F8,"mmmm"),EventData!C:C,"NO") -> 1 | I8: =SUM(G8:H8) -> 5 | K8: Arson* | L8: =COUNTIFS(EventData!A:A,"2022",EventData!H:H,"arson")+COUNTIFS(EventData!A:A,"2022",EventData!I:I,"arson") -> 0 | M8: =COUNTIFS(EventData!A:A,"2023",EventData!H:H,"arson")+COUNTIFS(EventData!A:A,"2023",EventData!I:I,"arson") -> 0 | N8: =COUNTIFS(EventData!A:A,"2024",EventData!H:H,"arson")+COUNTIFS(EventData!A:A,"2024",EventData!I:I,"arson") -> 13 | O8: =COUNTIFS(EventData!A:A,"2025",EventData!H:H,"arson")+COUNTIFS(EventData!A:A,"2025",EventData!I:I,"arson") -> 1 | P8: =SUM(L8:O8) -> 14 | R8: Disrupt (civil) aviation | S8: =COUNTIFS(EventData!A:A,"2022",EventData!J:J,"Disrupt (civil) aviation")+COUNTIFS(EventData!A:A,"2022",EventData!K:K,"Disrupt (civil) aviation") -> 1 | T8: =COUNTIFS(EventData!A:A,"2023",EventData!J:J,"Disrupt (civil) aviation")+COUNTIFS(EventData!A:A,"2023",EventData!K:K,"Disrupt (civil) aviation") -> 1 | U8: =COUNTIFS(EventData!A:A,"2024",EventData!J:J,"Disrupt (civil) aviation")+COUNTIFS(EventData!A:A,"2024",EventData!K:K,"Disrupt (civil) aviation") -> 2 | V8: =COUNTIFS(EventData!A:A,"2025",EventData!J:J,"Disrupt (civil) aviation")+COUNTIFS(EventData!A:A,"2025",EventData!K:K,"Disrupt (civil) aviation") -> 7 | W8: =SUM(S8:V8) -> 11 | Y8: Transport infrastructure | Z8: =COUNTIFS(EventData!A:A,"2022",EventData!L:L,"Transport infrastructure")+COUNTIFS(EventData!A:A,"2022",EventData!M:M,"Transport infrastructure") -> 0 | AA8: =COUNTIFS(EventData!A:A,"2023",EventData!L:L,"Transport infrastructure")+COUNTIFS(EventData!A:A,"2023",EventData!M:M,"Transport infrastructure") -> 1 | AB8: =COUNTIFS(EventData!A:A,"2024",EventData!L:L,"Transport infrastructure")+COUNTIFS(EventData!A:A,"2024",EventData!M:M,"Transport infrastructure") -> 6 | AC8: =COUNTIFS(EventData!A:A,"2025",EventData!L:L,"Transport infrastructure")+COUNTIFS(EventData!A:A,"2025",EventData!M:M,"Transport infrastructure") -> 1 | AD8: =SUM(Z8:AC8) -> 8 | AF8: Baltic Sea | AG8: =COUNTIFS(EventData!A:A,"2022",EventData!G:G,"*baltic sea*") -> 1 | AH8: =COUNTIFS(EventData!A:A,"2023",EventData!G:G,"*baltic sea*") -> 3 | AI8: =COUNTIFS(EventData!A:A,"2024",EventData!G:G,"*baltic sea*") -> 4 | AJ8: =COUNTIFS(EventData!A:A,"2025",EventData!G:G,"*baltic sea*") -> 2 | AK8: =SUM(AG8:AJ8) -> 10
F9: 44774 | G9: =COUNTIFS(EventData!D:D,"<=" & EOMONTH(F9,0),EventData!E:E,">=" & F9) -> 4 | H9: =COUNTIFS(EventData!A:A,YEAR(F9),EventData!B:B,TEXT(F9,"mmmm"),EventData!C:C,"NO") -> 0 | I9: =SUM(G9:H9) -> 4 | K9: Reconnaissance | L9: =COUNTIFS(EventData!A:A,"2022",EventData!H:H,"*recon*")+COUNTIFS(EventData!A:A,"2022",EventData!I:I,"*recon*") -> 4 | M9: =COUNTIFS(EventData!A:A,"2023",EventData!H:H,"*recon*")+COUNTIFS(EventData!A:A,"2023",EventData!I:I,"*recon*") -> 1 | N9: =COUNTIFS(EventData!A:A,"2024",EventData!H:H,"*recon*")+COUNTIFS(EventData!A:A,"2024",EventData!I:I,"*recon*") -> 6 | O9: =COUNTIFS(EventData!A:A,"2025",EventData!H:H,"*recon*")+COUNTIFS(EventData!A:A,"2025",EventData!I:I,"*recon*") -> 7 | P9: =SUM(L9:O9) -> 18 | R9: Inflict economic damage | S9: =COUNTIFS(EventData!A:A,"2022",EventData!J:J,"Inflict economic damage")+COUNTIFS(EventData!A:A,"2022",EventData!K:K,"Inflict economic damage") -> 0 | T9: =COUNTIFS(EventData!A:A,"2023",EventData!J:J,"Inflict economic damage")+COUNTIFS(EventData!A:A,"2023",EventData!K:K,"Inflict economic damage") -> 0 | U9: =COUNTIFS(EventData!A:A,"2024",EventData!J:J,"Inflict economic damage")+COUNTIFS(EventData!A:A,"2024",EventData!K:K,"Inflict economic damage") -> 12 | V9: =COUNTIFS(EventData!A:A,"2025",EventData!J:J,"Inflict economic damage")+COUNTIFS(EventData!A:A,"2025",EventData!K:K,"Inflict economic damage") -> 1 | W9: =SUM(S9:V9) -> 13 | Y9: Politician(s) | Z9: =COUNTIFS(EventData!A:A,"2022",EventData!L:L,"politician(s)")+COUNTIFS(EventData!A:A,"2022",EventData!M:M,"politician(s)") -> 1 | AA9: =COUNTIFS(EventData!A:A,"2023",EventData!L:L,"politician(s)")+COUNTIFS(EventData!A:A,"2023",EventData!M:M,"politician(s)") -> 4 | AB9: =COUNTIFS(EventData!A:A,"2024",EventData!L:L,"politician(s)")+COUNTIFS(EventData!A:A,"2024",EventData!M:M,"politician(s)") -> 4 | AC9: =COUNTIFS(EventData!A:A,"2025",EventData!L:L,"politician(s)")+COUNTIFS(EventData!A:A,"2025",EventData!M:M,"politician(s)") -> 0 | AD9: =SUM(Z9:AC9) -> 9 | AF9: Estonia | AG9: =COUNTIFS(EventData!A:A,"2022",EventData!G:G,"*estonia*") -> 1 | AH9: =COUNTIFS(EventData!A:A,"2023",EventData!G:G,"*estonia*") -> 5 | AI9: =COUNTIFS(EventData!A:A,"2024",EventData!G:G,"*estonia*") -> 2 | AJ9: =COUNTIFS(EventData!A:A,"2025",EventData!G:G,"*estonia*") -> 1 | AK9: =SUM(AG9:AJ9) -> 9
F10: 44805 | G10: =COUNTIFS(EventData!D:D,"<=" & EOMONTH(F10,0),EventData!E:E,">=" & F10) -> 5 | H10: =COUNTIFS(EventData!A:A,YEAR(F10),EventData!B:B,TEXT(F10,"mmmm"),EventData!C:C,"NO") -> 0 | I10: =SUM(G10:H10) -> 5 | K10: Sabotage* | L10: =COUNTIFS(EventData!A:A,"2022",EventData!H:H,"*sabotage*")+COUNTIFS(EventData!A:A,"2022",EventData!I:I,"*sabotage*") -> 1 | M10: =COUNTIFS(EventData!A:A,"2023",EventData!H:H,"*sabotage*")+COUNTIFS(EventData!A:A,"2023",EventData!I:I,"*sabotage*") -> 4 | N10: =COUNTIFS(EventData!A:A,"2024",EventData!H:H,"*sabotage*")+COUNTIFS(EventData!A:A,"2024",EventData!I:I,"*sabotage*") -> 16 | O10: =COUNTIFS(EventData!A:A,"2025",EventData!H:H,"*sabotage*")+COUNTIFS(EventData!A:A,"2025",EventData!I:I,"*sabotage*") -> 9 | P10: =SUM(L10:O10) -> 30 | R10: Preparation for potential sabotage | S10: =COUNTIFS(EventData!A:A,"2022",EventData!J:J,"*preparation for*")+COUNTIFS(EventData!A:A,"2022",EventData!K:K,"*preparation for*") -> 4 | T10: =COUNTIFS(EventData!A:A,"2023",EventData!J:J,"*preparation for*")+COUNTIFS(EventData!A:A,"2023",EventData!K:K,"*preparation for*") -> 1 | U10: =COUNTIFS(EventData!A:A,"2024",EventData!J:J,"*preparation for*")+COUNTIFS(EventData!A:A,"2024",EventData!K:K,"*preparation for*") -> 6 | V10: =COUNTIFS(EventData!A:A,"2025",EventData!J:J,"*preparation for*")+COUNTIFS(EventData!A:A,"2025",EventData!K:K,"*preparation for*") -> 3 | W10: =SUM(S10:V10) -> 14 | Y10: Pubic services | Z10: =COUNTIFS(EventData!A:A,"2022",EventData!L:L,"public services")+COUNTIFS(EventData!A:A,"2022",EventData!M:M,"public services") -> 0 | AA10: =COUNTIFS(EventData!A:A,"2023",EventData!L:L,"public services")+COUNTIFS(EventData!A:A,"2023",EventData!M:M,"public services") -> 0 | AB10: =COUNTIFS(EventData!A:A,"2024",EventData!L:L,"public services")+COUNTIFS(EventData!A:A,"2024",EventData!M:M,"public services") -> 8 | AC10: =COUNTIFS(EventData!A:A,"2025",EventData!L:L,"public services")+COUNTIFS(EventData!A:A,"2025",EventData!M:M,"public services") -> 2 | AD10: =SUM(Z10:AC10) -> 10 | AF10: Belgium | AG10: =COUNTIFS(EventData!A:A,"2022",EventData!G:G,"*belgium*") -> 0 | AH10: =COUNTIFS(EventData!A:A,"2023",EventData!G:G,"*belgium*") -> 2 | AI10: =COUNTIFS(EventData!A:A,"2024",EventData!G:G,"*belgium*") -> 1 | AJ10: =COUNTIFS(EventData!A:A,"2025",EventData!G:G,"*belgium*") -> 6 | AK10: =SUM(AG10:AJ10) -> 9
F11: 44835 | G11: =COUNTIFS(EventData!D:D,"<=" & EOMONTH(F11,0),EventData!E:E,">=" & F11) -> 6 | H11: =COUNTIFS(EventData!A:A,YEAR(F11),EventData!B:B,TEXT(F11,"mmmm"),EventData!C:C,"NO") -> 0 | I11: =SUM(G11:H11) -> 6 | K11: Influence operation | L11: =COUNTIFS(EventData!A:A,"2022",EventData!H:H,"*influence*")+COUNTIFS(EventData!A:A,"2022",EventData!I:I,"*influence*") -> 6 | M11: =COUNTIFS(EventData!A:A,"2023",EventData!H:H,"*influence*")+COUNTIFS(EventData!A:A,"2023",EventData!I:I,"*influence*") -> 10 | N11: =COUNTIFS(EventData!A:A,"2024",EventData!H:H,"*influence*")+COUNTIFS(EventData!A:A,"2024",EventData!I:I,"*influence*") -> 17 | O11: =COUNTIFS(EventData!A:A,"2025",EventData!H:H,"*influence*")+COUNTIFS(EventData!A:A,"2025",EventData!I:I,"*influence*") -> 10 | P11: =SUM(L11:O11) -> 43 | R11: Disrupt (military) aid to Ukraine | S11: =COUNTIFS(EventData!A:A,"2022",EventData!J:J,"Disrupt (military) aid to Ukraine")+COUNTIFS(EventData!A:A,"2022",EventData!K:K,"Disrupt (military) aid to Ukraine") -> 7 | T11: =COUNTIFS(EventData!A:A,"2023",EventData!J:J,"Disrupt (military) aid to Ukraine")+COUNTIFS(EventData!A:A,"2023",EventData!K:K,"Disrupt (military) aid to Ukraine") -> 8 | U11: =COUNTIFS(EventData!A:A,"2024",EventData!J:J,"Disrupt (military) aid to Ukraine")+COUNTIFS(EventData!A:A,"2024",EventData!K:K,"Disrupt (military) aid to Ukraine") -> 11 | V11: =COUNTIFS(EventData!A:A,"2025",EventData!J:J,"Disrupt (military) aid to Ukraine")+COUNTIFS(EventData!A:A,"2025",EventData!K:K,"Disrupt (military) aid to Ukraine") -> 4 | W11: =SUM(S11:V11) -> 30 | Y11: Energy / communications infrastructure | Z11: =COUNTIFS(EventData!A:A,"2022",EventData!L:L,"Energy / communications infrastructure")+COUNTIFS(EventData!A:A,"2022",EventData!M:M,"Energy / communications infrastructure") -> 2 | AA11: =COUNTIFS(EventData!A:A,"2023",EventData!L:L,"Energy / communications infrastructure")+COUNTIFS(EventData!A:A,"2023",EventData!M:M,"Energy / communications infrastructure") -> 2 | AB11: =COUNTIFS(EventData!A:A,"2024",EventData!L:L,"Energy / communications infrastructure")+COUNTIFS(EventData!A:A,"2024",EventData!M:M,"Energy / communications infrastructure") -> 5 | AC11: =COUNTIFS(EventData!A:A,"2025",EventData!L:L,"Energy / communications infrastructure")+COUNTIFS(EventData!A:A,"2025",EventData!M:M,"Energy / communications infrastructure") -> 5 | AD11: =SUM(Z11:AC11) -> 14 | AF11: Lithuania | AG11: =COUNTIFS(EventData!A:A,"2022",EventData!G:G,"*lithuania*") -> 0 | AH11: =COUNTIFS(EventData!A:A,"2023",EventData!G:G,"*lithuania*") -> 2 | AI11: =COUNTIFS(EventData!A:A,"2024",EventData!G:G,"*lithuania*") -> 5 | AJ11: =COUNTIFS(EventData!A:A,"2025",EventData!G:G,"*lithuania*") -> 2 | AK11: =SUM(AG11:AJ11) -> 9
F12: 44866 | G12: =COUNTIFS(EventData!D:D,"<=" & EOMONTH(F12,0),EventData!E:E,">=" & F12) -> 6 | H12: =COUNTIFS(EventData!A:A,YEAR(F12),EventData!B:B,TEXT(F12,"mmmm"),EventData!C:C,"NO") -> 0 | I12: =SUM(G12:H12) -> 6 | R12: Compromise domestic / EU politics | S12: =COUNTIFS(EventData!A:A,"2022",EventData!J:J,"Compromise domestic / EU politics")+COUNTIFS(EventData!A:A,"2022",EventData!K:K,"Compromise domestic / EU politics") -> 2 | T12: =COUNTIFS(EventData!A:A,"2023",EventData!J:J,"Compromise domestic / EU politics")+COUNTIFS(EventData!A:A,"2023",EventData!K:K,"Compromise domestic / EU politics") -> 6 | U12: =COUNTIFS(EventData!A:A,"2024",EventData!J:J,"Compromise domestic / EU politics")+COUNTIFS(EventData!A:A,"2024",EventData!K:K,"Compromise domestic / EU politics") -> 16 | V12: =COUNTIFS(EventData!A:A,"2025",EventData!J:J,"Compromise domestic / EU politics")+COUNTIFS(EventData!A:A,"2025",EventData!K:K,"Compromise domestic / EU politics") -> 8 | W12: =SUM(S12:V12) -> 32 | Y12: Civil aviation | Z12: =COUNTIFS(EventData!A:A,"2022",EventData!L:L,"Civil aviation")+COUNTIFS(EventData!A:A,"2022",EventData!M:M,"Civil aviation") -> 1 | AA12: =COUNTIFS(EventData!A:A,"2023",EventData!L:L,"Civil aviation")+COUNTIFS(EventData!A:A,"2023",EventData!M:M,"Civil aviation") -> 1 | AB12: =COUNTIFS(EventData!A:A,"2024",EventData!L:L,"Civil aviation")+COUNTIFS(EventData!A:A,"2024",EventData!M:M,"Civil aviation") -> 5 | AC12: =COUNTIFS(EventData!A:A,"2025",EventData!L:L,"Civil aviation")+COUNTIFS(EventData!A:A,"2025",EventData!M:M,"Civil aviation") -> 9 | AD12: =SUM(Z12:AC12) -> 16 | AF12: Spain | AG12: =COUNTIFS(EventData!A:A,"2022",EventData!G:G,"*spain*") -> 1 | AH12: =COUNTIFS(EventData!A:A,"2023",EventData!G:G,"*spain*") -> 2 | AI12: =COUNTIFS(EventData!A:A,"2024",EventData!G:G,"*spain*") -> 4 | AJ12: =COUNTIFS(EventData!A:A,"2025",EventData!G:G,"*spain*") -> 1 | AK12: =SUM(AG12:AJ12) -> 8
F13: 44896 | G13: =COUNTIFS(EventData!D:D,"<=" & EOMONTH(F13,0),EventData!E:E,">=" & F13) -> 6 | H13: =COUNTIFS(EventData!A:A,YEAR(F13),EventData!B:B,TEXT(F13,"mmmm"),EventData!C:C,"NO") -> 1 | I13: =SUM(G13:H13) -> 7 | K13: * Includes preparations for & attempted | R13: Disrupt daily life | S13: =COUNTIFS(EventData!A:A,"2022",EventData!J:J,"Disrupt daily life")+COUNTIFS(EventData!A:A,"2022",EventData!K:K,"Disrupt daily life") -> 1 | T13: =COUNTIFS(EventData!A:A,"2023",EventData!J:J,"Disrupt daily life")+COUNTIFS(EventData!A:A,"2023",EventData!K:K,"Disrupt daily life") -> 7 | U13: =COUNTIFS(EventData!A:A,"2024",EventData!J:J,"Disrupt daily life")+COUNTIFS(EventData!A:A,"2024",EventData!K:K,"Disrupt daily life") -> 28 | V13: =COUNTIFS(EventData!A:A,"2025",EventData!J:J,"Disrupt daily life")+COUNTIFS(EventData!A:A,"2025",EventData!K:K,"Disrupt daily life") -> 10 | W13: =SUM(S13:V13) -> 46 | Y13: Internet / Social media / News | Z13: =COUNTIFS(EventData!A:A,"2022",EventData!L:L,"Internet / Social media / news")+COUNTIFS(EventData!A:A,"2022",EventData!M:M,"Internet / Social media / news") -> 1 | AA13: =COUNTIFS(EventData!A:A,"2023",EventData!L:L,"Internet / Social media / news")+COUNTIFS(EventData!A:A,"2023",EventData!M:M,"Internet / Social media / news") -> 4 | AB13: =COUNTIFS(EventData!A:A,"2024",EventData!L:L,"Internet / Social media / news")+COUNTIFS(EventData!A:A,"2024",EventData!M:M,"Internet / Social media / news") -> 8 | AC13: =COUNTIFS(EventData!A:A,"2025",EventData!L:L,"Internet / Social media / news")+COUNTIFS(EventData!A:A,"2025",EventData!M:M,"Internet / Social media / news") -> 6 | AD13: =SUM(Z13:AC13) -> 19 | AF13: Finland | AG13: =COUNTIFS(EventData!A:A,"2022",EventData!G:G,"*finland*") -> 0 | AH13: =COUNTIFS(EventData!A:A,"2023",EventData!G:G,"*finland*") -> 2 | AI13: =COUNTIFS(EventData!A:A,"2024",EventData!G:G,"*finland*") -> 4 | AJ13: =COUNTIFS(EventData!A:A,"2025",EventData!G:G,"*finland*") -> 2 | AK13: =SUM(AG13:AJ13) -> 8
F14: 44927 | G14: =COUNTIFS(EventData!D:D,"<=" & EOMONTH(F14,0),EventData!E:E,">=" & F14) -> 7 | H14: =COUNTIFS(EventData!A:A,YEAR(F14),EventData!B:B,TEXT(F14,"mmmm"),EventData!C:C,"NO") -> 1 | I14: =SUM(G14:H14) -> 8 | K14: ** Includes plots & attempts | Y14: Military / weapons production infrastructure | Z14: =COUNTIFS(EventData!A:A,"2022",EventData!L:L,"Military / weapons production infrastructure")+COUNTIFS(EventData!A:A,"2022",EventData!M:M,"Military / weapons production infrastructure") -> 5 | AA14: =COUNTIFS(EventData!A:A,"2023",EventData!L:L,"Military / weapons production infrastructure")+COUNTIFS(EventData!A:A,"2023",EventData!M:M,"Military / weapons production infrastructure") -> 2 | AB14: =COUNTIFS(EventData!A:A,"2024",EventData!L:L,"Military / weapons production infrastructure")+COUNTIFS(EventData!A:A,"2024",EventData!M:M,"Military / weapons production infrastructure") -> 4 | AC14: =COUNTIFS(EventData!A:A,"2025",EventData!L:L,"Military / weapons production infrastructure")+COUNTIFS(EventData!A:A,"2025",EventData!M:M,"Military / weapons production infrastructure") -> 9 | AD14: =SUM(Z14:AC14) -> 20 | AF14: Italy | AG14: =COUNTIFS(EventData!A:A,"2022",EventData!G:G,"*italy*") -> 1 | AH14: =COUNTIFS(EventData!A:A,"2023",EventData!G:G,"*italy*") -> 1 | AI14: =COUNTIFS(EventData!A:A,"2024",EventData!G:G,"*italy*") -> 2 | AJ14: =COUNTIFS(EventData!A:A,"2025",EventData!G:G,"*italy*") -> 3 | AK14: =SUM(AG14:AJ14) -> 7
F15: 44958 | G15: =COUNTIFS(EventData!D:D,"<=" & EOMONTH(F15,0),EventData!E:E,">=" & F15) -> 7 | H15: =COUNTIFS(EventData!A:A,YEAR(F15),EventData!B:B,TEXT(F15,"mmmm"),EventData!C:C,"NO") -> 0 | I15: =SUM(G15:H15) -> 7 | Y15: Public space | Z15: =COUNTIFS(EventData!A:A,"2022",EventData!L:L,"*public space*")+COUNTIFS(EventData!A:A,"2022",EventData!M:M,"*public space*") -> 4 | AA15: =COUNTIFS(EventData!A:A,"2023",EventData!L:L,"*public space*")+COUNTIFS(EventData!A:A,"2023",EventData!M:M,"*public space*") -> 5 | AB15: =COUNTIFS(EventData!A:A,"2024",EventData!L:L,"*public space*")+COUNTIFS(EventData!A:A,"2024",EventData!M:M,"*public space*") -> 24 | AC15: =COUNTIFS(EventData!A:A,"2025",EventData!L:L,"*public space*")+COUNTIFS(EventData!A:A,"2025",EventData!M:M,"*public space*") -> 6 | AD15: =SUM(Z15:AC15) -> 39 | AF15: Romania | AG15: =COUNTIFS(EventData!A:A,"2022",EventData!G:G,"*romania*") -> 0 | AH15: =COUNTIFS(EventData!A:A,"2023",EventData!G:G,"*romania*") -> 1 | AI15: =COUNTIFS(EventData!A:A,"2024",EventData!G:G,"*romania*") -> 3 | AJ15: =COUNTIFS(EventData!A:A,"2025",EventData!G:G,"*romania*") -> 3 | AK15: =SUM(AG15:AJ15) -> 7
F16: 44986 | G16: =COUNTIFS(EventData!D:D,"<=" & EOMONTH(F16,0),EventData!E:E,">=" & F16) -> 8 | H16: =COUNTIFS(EventData!A:A,YEAR(F16),EventData!B:B,TEXT(F16,"mmmm"),EventData!C:C,"NO") -> 1 | I16: =SUM(G16:H16) -> 9 | AF16: Czechia | AG16: =COUNTIFS(EventData!A:A,"2022",EventData!G:G,"*czechia*") -> 0 | AH16: =COUNTIFS(EventData!A:A,"2023",EventData!G:G,"*czechia*") -> 1 | AI16: =COUNTIFS(EventData!A:A,"2024",EventData!G:G,"*czechia*") -> 3 | AJ16: =COUNTIFS(EventData!A:A,"2025",EventData!G:G,"*czechia*") -> 1 | AK16: =SUM(AG16:AJ16) -> 5
F17: 45017 | G17: =COUNTIFS(EventData!D:D,"<=" & EOMONTH(F17,0),EventData!E:E,">=" & F17) -> 7 | H17: =COUNTIFS(EventData!A:A,YEAR(F17),EventData!B:B,TEXT(F17,"mmmm"),EventData!C:C,"NO") -> 0 | I17: =SUM(G17:H17) -> 7 | AF17: Bulgaria | AG17: =COUNTIFS(EventData!A:A,"2022",EventData!G:G,"*bulgaria*") -> 1 | AH17: =COUNTIFS(EventData!A:A,"2023",EventData!G:G,"*bulgaria*") -> 2 | AI17: =COUNTIFS(EventData!A:A,"2024",EventData!G:G,"*bulgaria*") -> 1 | AJ17: =COUNTIFS(EventData!A:A,"2025",EventData!G:G,"*bulgaria*") -> 1 | AK17: =SUM(AG17:AJ17) -> 5
F18: 45047 | G18: =COUNTIFS(EventData!D:D,"<=" & EOMONTH(F18,0),EventData!E:E,">=" & F18) -> 6 | H18: =COUNTIFS(EventData!A:A,YEAR(F18),EventData!B:B,TEXT(F18,"mmmm"),EventData!C:C,"NO") -> 1 | I18: =SUM(G18:H18) -> 7 | AF18: Sweden | AG18: =COUNTIFS(EventData!A:A,"2022",EventData!G:G,"*sweden*") -> 0 | AH18: =COUNTIFS(EventData!A:A,"2023",EventData!G:G,"*sweden*") -> 1 | AI18: =COUNTIFS(EventData!A:A,"2024",EventData!G:G,"*sweden*") -> 2 | AJ18: =COUNTIFS(EventData!A:A,"2025",EventData!G:G,"*sweden*") -> 2 | AK18: =SUM(AG18:AJ18) -> 5
F19: 45078 | G19: =COUNTIFS(EventData!D:D,"<=" & EOMONTH(F19,0),EventData!E:E,">=" & F19) -> 7 | H19: =COUNTIFS(EventData!A:A,YEAR(F19),EventData!B:B,TEXT(F19,"mmmm"),EventData!C:C,"NO") -> 0 | I19: =SUM(G19:H19) -> 7 | AF19: Austria | AG19: =COUNTIFS(EventData!A:A,"2022",EventData!G:G,"*austria*") -> 1 | AH19: =COUNTIFS(EventData!A:A,"2023",EventData!G:G,"*austria*") -> 1 | AI19: =COUNTIFS(EventData!A:A,"2024",EventData!G:G,"*austria*") -> 1 | AJ19: =COUNTIFS(EventData!A:A,"2025",EventData!G:G,"*austria*") -> 1 | AK19: =SUM(AG19:AJ19) -> 4
F20: 45108 | G20: =COUNTIFS(EventData!D:D,"<=" & EOMONTH(F20,0),EventData!E:E,">=" & F20) -> 7 | H20: =COUNTIFS(EventData!A:A,YEAR(F20),EventData!B:B,TEXT(F20,"mmmm"),EventData!C:C,"NO") -> 1 | I20: =SUM(G20:H20) -> 8 | AF20: Switzerland | AG20: =COUNTIFS(EventData!A:A,"2022",EventData!G:G,"*switzerland*") -> 0 | AH20: =COUNTIFS(EventData!A:A,"2023",EventData!G:G,"*switzerland*") -> 1 | AI20: =COUNTIFS(EventData!A:A,"2024",EventData!G:G,"*switzerland*") -> 2 | AJ20: =COUNTIFS(EventData!A:A,"2025",EventData!G:G,"*switzerland*") -> 1 | AK20: =SUM(AG20:AJ20) -> 4
F21: 45139 | G21: =COUNTIFS(EventData!D:D,"<=" & EOMONTH(F21,0),EventData!E:E,">=" & F21) -> 10 | H21: =COUNTIFS(EventData!A:A,YEAR(F21),EventData!B:B,TEXT(F21,"mmmm"),EventData!C:C,"NO") -> 0 | I21: =SUM(G21:H21) -> 10 | AF21: Denmark | AG21: =COUNTIFS(EventData!A:A,"2022",EventData!G:G,"*denmark*") -> 0 | AH21: =COUNTIFS(EventData!A:A,"2023",EventData!G:G,"*denmark*") -> 0 | AI21: =COUNTIFS(EventData!A:A,"2024",EventData!G:G,"*denmark*") -> 1 | AJ21: =COUNTIFS(EventData!A:A,"2025",EventData!G:G,"*denmark*") -> 3 | AK21: =SUM(AG21:AJ21) -> 4
